Workbook
Name _00_ANOS_FIN: '[1]Lista desplegableGeneral'!$B$3:$B$16
Name _00_ANOS_INICIO_: '[1]Lista desplegableGeneral'!$A$3:$A$13
Name _00_CAT_GASTO: '[1]Lista desplegableGeneral'!$H$3:$H$5
Name _00_ESPECIFICA_DETALLE_GASTO: '[1]Lista desplegableGeneral'!$M$3:$M$475
Name _00_ESPECIFICA_GASTO: '[1]Lista desplegableGeneral'!$L$3:$L$170
Name _00_FUENTE_FINAC: '[1]Lista desplegableGeneral'!$G$3:$G$7
Name _00_GENERICA_GASTO: '[1]Lista desplegableGeneral'!$I$3:$I$11
Name _00_SI_NO: '[1]Lista desplegableGeneral'!$F$3:$F$4
Name _00_SUBGENERICA_DETALLE_GASTO: '[1]Lista desplegableGeneral'!$K$3:$K$79
Name _00_SUBGENERICA_GASTO: '[1]Lista desplegableGeneral'!$J$3:$J$30
Name _01_SECTORES_GNGRGL: [1]listaDesplegableUE!$A$3:$C$34
Name _1._ORDEN_DE_COMPRA: '[1]Lista desplegableGeneral'!#REF!
Name _2._ORDEN_DE_SERVICIO: '[1]Lista desplegableGeneral'!#REF!
Name AA: [2]Hoja1!$A$1:$A$86
Name ACTIVIDAD_PRESUPUESTAL: [3]columnas!$A$2:$A$5
Name BASE: [4]INFORME!$A$3:$M$1002
Name BASE1: [4]INFORME!$A$4:$M$1048576
Name BATER: #REF!
Name BATER: #REF!
Name BATER: #REF!
Name BEJI: [5]DATA!$B$4:$C$26
Name BET: [6]Hoja9!$A$40:$B$70
Name buscar: #REF!
Name buscar: #REF!
Name buscar: #REF!
Name cabe: #REF!
Name cabe: #REF!
Name cabe: #REF!
Name CAMALEON: #REF!
Name CAMALEON: #REF!
Name CAMALEON: #REF!
Name cambiar: #REF!
Name cambiar: #REF!
Name cambiar: #REF!
Name cargo: [7]Enero!$A$5:$D$196
Name case: [8]poi!$A$1:$S$102
Name cave: #REF!
Name cave: #REF!
Name cave: #REF!
Name certif: #REF!
Name certif: #REF!
Name certif: #REF!
Name CLASIFI: #REF!
Name CLASIFI: #REF!
Name CLASIFI: #REF!
Name COLUMNA1_F1: [9]LISTA_NIVEL1!$A$21:$C$33
Name como: #REF!
Name como: #REF!
Name como: #REF!
Name costo: [10]Hoja4!$A$53:$B$103
Name dbidud: #REF!
Name dbidud: #REF!
Name dbidud: #REF!
Name dedos: #REF!
Name dedos: #REF!
Name dedos: #REF!
Name DESCRIPCION: [11]!PRESUPUESTO[[#All],[CLASIFICADOR]:[S1]]
Name EJECUTORAS_F3: #REF!
Name encuentra: #REF!
Name encuentra: #REF!

Sheet INICIO
E2: Programa de Empleo Temporal "LLAMKASUN PERÚ"
AL9: % de Avance (devengado)
O10: Ejecución PIM 2026 | Y10: CERTIFICACIONES Ejecución de CCPs
AQ16: =+PIM!Z24 -> 0.46310112
O23: ® UNIDAD FUNCIONAL DE PLANEAMIENTO Y PRESUPUESTO

Sheet PIM
M1: EJECUCIÓN PRESUPUESTAL 2025
AH2: Programa de Empleo Temporal "LLAMKASUN PERÚ"
GC3: PIM | GD3: =+M6 -> 452587256 | GG3: PIM | GH3: =+M6 -> 452587256
M4: PIM (S/) | AS4: EJEC. + PROY. MENSUAL
GC5: Poco avance | GD5: 80 | GE5: 0.98 | GG5: Muy bueno | GH5: 50 | GI5: 0.98
M6: =+SUBTOTAL(9,Tabla1[PIM]) -> 452587256 | GC6: avance regular | GD6: 17 | GE6: 0.96 | GG6: Buen avance | GH6: 40 | GI6: 0.95
AS7: ENE | AU7: =+DETALLE_PIM!AI1 -> 1423292.2 | GC7: Bueno | GD7: 2 | GE7: 0.95 | GG7: Avance regular | GH7: 7 | GI7: 0.85
AS8: FEB | AU8: =+DETALLE_PIM!AJ1 -> 1908012.2 | GC8: My bueno | GD8: 1 | GE8: 0.5 | GG8: Bajo avance | GH8: 3 | GI8: 0.5
AS9: MAR | AU9: =+DETALLE_PIM!AK1 -> 2592566.7 | GC9: TOTAL | GD9: =+SUM(GD5:GD8) -> 100 | GE9: 0 | GG9: TOTAL | GH9: =+SUM(GH5:GH8) -> 100 | GI9: 0
M10: CERTIFICADO (S/) | V10: % Avance (Certificación) | AJ10: PIM No Certificado (S/) | AS10: MAR' | AU10: =+DETALLE_PIM!AL1 -> 1.9663774e+08
AS11: ABR | AU11: =+DETALLE_PIM!AM1 -> 2150196.8 | GC11: CERT | GD11: =+M12 -> 4.4491515e+08 | GG11: dev | GH11: =+M21 -> 2.0959367e+08
M12: =+SUBTOTAL(9,Tabla1[CERTIFICADO]) -> 4.4491515e+08 | AJ12: =+DETALLE_PIM!U1-DETALLE_PIM!X1 -> 7672110.8 | AS12: MAY | AU12: =+DETALLE_PIM!AN1 -> 2409957.3 | GC12: % AVANCE | GD12: =+IFERROR(GD11/GD3,0) -> 0.98304833 | GG12: % AVANCE | GH12: =+IFERROR(GH11/GH3,0) -> 0.46310112
AS13: JUN | AU13: =+DETALLE_PIM!AO1 -> 2472710.9
M14: COMP. ANUAL (S/) | AS14: JUL | AU14: =+DETALLE_PIM!AP1 -> 171124.46 | GC14: Grados | GD14: =+GD12*PI() -> 3.0883374 | GG14: Grados | GH14: =+GH12*PI() -> 1.4548751
M15: =+SUBTOTAL(9,Tabla1[COMP. ANUAL]) -> 2.2238882e+08 | Z15: =+GD12 -> 0.98304833 | AS15: AGO | AU15: =+DETALLE_PIM!AQ1 -> 53719157
M16: CERT - COMP. ANUAL | AS16: SET | AU16: =+DETALLE_PIM!AR1 -> 1.7352122e+08
M17: =+M12-M15 -> 2.2252632e+08 | AS17: OCT | AU17: =+DETALLE_PIM!AS1 -> 7329009.3 | GD17: X | GE17: Y | GH17: X | GI17: Y
AS18: NOV | AU18: =+DETALLE_PIM!AT1 -> 2216583.5 | GC18: Inicial | GD18: 0 | GE18: 0 | GG18: Inicial | GH18: 0 | GI18: 0
M19: DEVENGADO (S/) | V19: % de Avance (devengado) | AJ19: PIM por DEVENGAR (S/) | AS19: DIC | AU19: =+DETALLE_PIM!AU1 -> 6035690.4 | GC19: Final | GD19: =COS(GD14)*-1 -> 0.99858227 | GE19: =+SIN(GD14) -> 0.053230079 | GG19: Final | GH19: =COS(GH14)*-1 -> -0.1156618 | GI19: =+SIN(GH14) -> 0.99328865
M21: =+SUBTOTAL(9,Tabla1[DEVENGADO2]) -> 2.0959367e+08 | AJ21: =+M6-M21 -> 2.4299359e+08 | AS21: EJEC. PROYECTADA
AS22: =+DETALLE_PIM!AV1 -> 452587256
Z24: =+GH12 -> 0.46310112 | AS24: SALDO PROYECTADO
AS25: =+DETALLE_PIM!AW1 -> 0
AS26: PIM no DEVENGADO
A27: ® UFPP-2025 | M27: ® Unidad Funcional de Planeamiento y Presupuesto-2025 | AS27: =+M6-M15 -> 2.3019843e+08
GD28: =+#REF!+1 -> #REF! | GF28: =+#REF!+1 -> #REF! | GH28: =+GF28/#REF! -> #REF! | GJ28: LABORABLE | GL28: JUEVES
GD29: =+GD28+1 -> #REF! | GF29: =+GF28+1 -> #REF! | GH29: =+GF29/#REF! -> #REF! | GJ29: LABORABLE | GL29: VIERNES
GD30: =+GD29+1 -> #REF! | GF30: =+GF29+1 -> #REF! | GH30: =+GF30/#REF! -> #REF! | GJ30: LABORABLE | GL30: SÁBADO
GD31: =+GD30+1 -> #REF! | GF31: =+GF30+1 -> #REF! | GH31: =+GF31/#REF! -> #REF! | GJ31: LABORABLE | GL31: DOMINGO
GD32: =+GD31+1 -> #REF! | GF32: =+GF31+1 -> #REF! | GH32: =+GF32/#REF! -> #REF! | GJ32: LABORABLE | GL32: LUNES
GD33: =+GD32+1 -> #REF! | GF33: =+GF32+1 -> #REF! | GH33: =+GF33/#REF! -> #REF! | GJ33: LABORABLE | GL33: MARTES
GD34: =+GD33+1 -> #REF! | GF34: =+GF33+1 -> #REF! | GH34: =+GF34/#REF! -> #REF! | GJ34: LABORABLE | GL34: MIÉRCOLES
GD35: =+GD34+1 -> #REF! | GF35: =+GF34+1 -> #REF! | GH35: =+GF35/#REF! -> #REF! | GJ35: LABORABLE | GL35: JUEVES
GD36: =+GD35+1 -> #REF! | GF36: =+GF35+1 -> #REF! | GH36: =+GF36/#REF! -> #REF! | GJ36: LABORABLE | GL36: VIERNES
GD37: =+GD36+1 -> #REF! | GF37: =+GF36+1 -> #REF! | GH37: =+GF37/#REF! -> #REF! | GJ37: LABORABLE | GL37: SÁBADO
GD38: =+GD37+1 -> #REF! | GF38: =+GF37+1 -> #REF! | GH38: =+GF38/#REF! -> #REF! | GJ38: LABORABLE | GL38: DOMINGO
GD39: =+GD38+1 -> #REF! | GF39: =+GF38+1 -> #REF! | GH39: =+GF39/#REF! -> #REF! | GJ39: LABORABLE | GL39: LUNES
GD40: =+GD39+1 -> #REF! | GF40: =+GF39+1 -> #REF! | GH40: =+GF40/#REF! -> #REF! | GJ40: LABORABLE | GL40: MARTES
... GD131: =+GD130+1 -> #REF! | GF131: =+GF130+1 -> #REF! | GH131: =+GF131/#REF! -> #REF! | GJ131: LABORABLE | GL131: MARTES
AA132: 47616.35 | GD132: =+GD131+1 -> #REF! | GF132: =+GF131+1 -> #REF! | GH132: =+GF132/#REF! -> #REF! | GJ132: LABORABLE | GL132: MIÉRCOLES
...

Sheet DETALLE_PIM
A1: PRESUPUESTO 2026 - UE: 005 - PROGRAMA DE EMPLEO TEMPORAL "LLAMKASUN PERÚ" | L1: EJECUCIÓN Y PROYECCIÓN | T1: =+SUBTOTAL(9,T5:T822) -> 452488556 | U1: =+SUBTOTAL(9,U5:U822) -> 452587256 | X1: =+SUBTOTAL(9,X5:X822) -> 4.4491515e+08 | Y1: =+IFERROR(X1/U1,0) -> 0.98304833 | Z1: =+SUBTOTAL(9,Z5:Z822) -> 7672110.8 | AB1: =+SUBTOTAL(9,AB5:AB822) -> 2.2238882e+08 | AC1: =+SUBTOTAL(9,AC5:AC822) -> 2.3019843e+08 | AD1: =+SUBTOTAL(9,AD5:AD822) -> 2.1411364e+08 | AF1: =+SUBTOTAL(9,AF5:AF822) -> 2.0959367e+08 | AG1: =+IFERROR(AF1/U1,0) -> 0.46310112 | AH1: =+SUBTOTAL(9,AH5:AH822) -> 2.4299359e+08 | AI1: =+SUBTOTAL(9,AI5:AI822) -> 1423292.2 | AJ1: =+SUBTOTAL(9,AJ5:AJ822) -> 1908012.2 | AK1: =+SUBTOTAL(9,AK5:AK822) -> 2592566.7 | AL1: =+SUBTOTAL(9,AL5:AL822) -> 1.9663774e+08 | AM1: =+SUBTOTAL(9,AM5:AM822) -> 2150196.8 | AN1: =+SUBTOTAL(9,AN5:AN822) -> 2409957.3 | AO1: =+SUBTOTAL(9,AO5:AO822) -> 2472710.9 | ... AW1: =+SUBTOTAL(9,AW5:AW822) -> 0
Z2: =+AF2-Z1 -> -7672110.8
AI3: EJECUCIÓN | AP3: PROYECCIÓN DEL GASTO
A4: Prog. Pptal. | B4: fte. Fto. | C4: DISP. LEGAL | D4: PRODUCTO | E4: COD ACT_PPTAL | F4: FINALIDAD | G4: ACTIVIDAD OPERATIVA | H4: CONCEPTO DE GASTO 1 | I4: RESTRINGIDA | J4: OF NAC / UT /TRANSF | K4: CENTRO DE COSTO | L4: UF / UT/ | M4: SEC.FUN. | N4: Sec. Fun. (Meta Pptal.) | O4: NEMONICO | P4: GEN. DE GASTO | Q4: CLASIFICADOR3 | R4: CLASIFICADOR2 | S4: DESCRIPCION | T4: PIA | U4: PIM | V4: . | W4: Columna2 | X4: CERTIFICADO | Y4: % CERT | Z4: NO CERT | AA4: .3 | AB4: COMP. ANUAL | AC4: PIM sin COMP | AD4: COMPROMISO | AE4: .4 | AF4: DEVENGADO2 | AG4: % EJEC | AH4: CERT NO DEV | AI4: ENE | AJ4: FEB | AK4: MAR | AL4: ABR | AM4: MAY | AN4: JUN | AO4: JUL | AP4: JUL2 | AQ4: AGO | AR4: SET | AS4: OCT | AT4: NOV | AU4: DIC | AV4: TOTAL | AW4: SALDO / DEFICIT
A5: 0073.PROGRAMA PARA LA GENERACION DEL EMPLEO SOCIAL INCLUSIVO - TRABAJA PERU | B5: 00 | C5: 01. PIA 2026 | D5: 3000001.ACCIONES COMUNES | E5: 5000276.GESTION DEL PROGRAMA | F5: 0047173.GESTION DEL PROGRAMA | G5: AOI00106600144. GESTIÓN OPERATIVA - UT AMAZONAS | H5: CAS | I5: RESTRINGIDA | J5: UFAF | K5: UFAF | L5: UT AMAZONAS | M5: 0001. UT AMAZONAS | N5: 0001 | O5: UT AMAZONAS | P5: 5-21.PERSONAL Y OBLIGACIONES SOCIALES | Q5: 21 1 9 1 4. AGUINALDOS DE CONTRATO ADMINISTRATIVO DE SERVICIOS | R5: 21 1 9 1 4 | S5: AGUINALDOS DE CONTRATO ADMINISTRATIVO DE SERVICIOS | T5: 600 | U5: 600 | X5: 600 | Y5: =+IFERROR(X5/U5,0) -> 1 | Z5: =+U5-X5 -> 0 | AB5: 600 | AC5: 0 | AD5: 0 | AF5: 0 | AG5: =+IFERROR(AF5/U5,0) -> 0 | AH5: =+Tabla1[[#This Row],[PIM]]-Tabla1[[#This Row],[DEVENGADO2]] -> 600 | AI5: 0 | AJ5: 0 | AK5: 0 | AL5: 0 | AM5: 0 | AN5: 0 | AO5: 0 | AP5: 300 | AQ5: 0 | AR5: 0 | AS5: 0 | AT5: 0 | AU5: 300 | AV5: =+SUM(AI5:AU5) -> 600 | AW5: =+U5-AV5 -> 0
A6: 0073.PROGRAMA PARA LA GENERACION DEL EMPLEO SOCIAL INCLUSIVO - TRABAJA PERU | B6: 00 | C6: 01. PIA 2026 | D6: 3000001.ACCIONES COMUNES | E6: 5000276.GESTION DEL PROGRAMA | F6: 0047173.GESTION DEL PROGRAMA | G6: AOI00106600144. GESTIÓN OPERATIVA - UT AMAZONAS | H6: CAS | I6: RESTRINGIDA | J6: UFAF | K6: UFAF | L6: UT AMAZONAS | M6: 0001. UT AMAZONAS | N6: 0001 | O6: UT AMAZONAS | P6: 5-21.PERSONAL Y OBLIGACIONES SOCIALES | Q6: 21 113 1 1. CONTRATO ADMINISTRATIVO DE SERVICIOS - INDETERMINADO | R6: 21 113 1 1 | S6: CONTRATO ADMINISTRATIVO DE SERVICIOS - INDETERMINADO | T6: 33170 | U6: 34371 | X6: 34371 | Y6: =+IFERROR(X6/U6,0) -> 1 | Z6: =+U6-X6 -> 0 | AB6: 34371 | AC6: 0 | AD6: 20049.33 | AF6: 20049.33 | AG6: =+IFERROR(AF6/U6,0) -> 0.58332111 | AH6: =+Tabla1[[#This Row],[PIM]]-Tabla1[[#This Row],[DEVENGADO2]] -> 14321.67 | AI6: 2864.19 | AJ6: 2864.19 | AK6: 2864.19 | AL6: 2864.19 | AM6: 2864.19 | AN6: 2864.19 | AO6: 2864.19 | AP6: 0 | AQ6: 2764.19 | AR6: 2764.19 | AS6: 2764.19 | AT6: 2764.19 | AU6: 3264.91 | AV6: =+SUM(AI6:AU6) -> 34371 | AW6: =+U6-AV6 -> 0
A7: 0073.PROGRAMA PARA LA GENERACION DEL EMPLEO SOCIAL INCLUSIVO - TRABAJA PERU | B7: 00 | C7: 01. PIA 2026 | D7: 3000001.ACCIONES COMUNES | E7: 5000276.GESTION DEL PROGRAMA | F7: 0047173.GESTION DEL PROGRAMA | G7: AOI00106600144. GESTIÓN OPERATIVA - UT AMAZONAS | H7: CAS | I7: RESTRINGIDA | J7: UFAF | K7: UFAF | L7: UT AMAZONAS | M7: 0001. UT AMAZONAS | N7: 0001 | O7: UT AMAZONAS | P7: 5-21.PERSONAL Y OBLIGACIONES SOCIALES | Q7: 21 3 1 115. CONTRIBUCIONES A ESSALUD DE CONTRATO ADMINISTRATIVO DE SERVICIOS | R7: 21 3 1 115 | S7: CONTRIBUCIONES A ESSALUD DE CONTRATO ADMINISTRATIVO DE SERVICIOS | T7: 2760 | U7: 2673 | X7: 2673 | Y7: =+IFERROR(X7/U7,0) -> 1 | Z7: =+U7-X7 -> 0 | AB7: 2673 | AC7: 0 | AD7: 1559.25 | AF7: 1559.25 | AG7: =+IFERROR(AF7/U7,0) -> 0.58333333 | AH7: =+Tabla1[[#This Row],[PIM]]-Tabla1[[#This Row],[DEVENGADO2]] -> 1113.75 | AI7: 222.75 | AJ7: 222.75 | AK7: 222.75 | AL7: 222.75 | AM7: 222.75 | AN7: 222.75 | AO7: 222.75 | AP7: 0 | AQ7: 230 | AR7: 230 | AS7: 230 | AT7: 230 | AU7: 193.75 | AV7: =+SUM(AI7:AU7) -> 2673 | AW7: =+U7-AV7 -> 0
A8: 0073.PROGRAMA PARA LA GENERACION DEL EMPLEO SOCIAL INCLUSIVO - TRABAJA PERU | B8: 00 | C8: 01. PIA 2026 | D8: 3000001.ACCIONES COMUNES | E8: 5000276.GESTION DEL PROGRAMA | F8: 0047173.GESTION DEL PROGRAMA | G8: AOI00106600144. GESTIÓN OPERATIVA - UT AMAZONAS | H8: COMBUSTIBLE | I8: NO RESTRINGIDA | J8: UFAF | K8: UFAF | L8: UT AMAZONAS | M8: 0001. UT AMAZONAS | N8: 0001 | O8: UT AMAZONAS | P8: 5-23.BIENES Y SERVICIOS | Q8: 23 1 3 1 1. COMBUSTIBLES Y CARBURANTES | R8: 23 1 3 1 1 | S8: COMBUSTIBLES Y CARBURANTES | T8: 3750 | U8: 0 | X8: 0 | Y8: =+IFERROR(X8/U8,0) -> 0 | Z8: =+U8-X8 -> 0 | AB8: 0 | AC8: 0 | AD8: 0 | AF8: 0 | AG8: =+IFERROR(AF8/U8,0) -> 0 | AH8: =+Tabla1[[#This Row],[PIM]]-Tabla1[[#This Row],[DEVENGADO2]] -> 0 | AI8: 0 | AJ8: 0 | AK8: 0 | AL8: 0 | AM8: 0 | AN8: 0 | AO8: 0 | AP8: 0 | AQ8: 0 | AR8: 0 | AS8: 0 | AT8: 0 | AU8: 0 | AV8: =+SUM(AI8:AU8) -> 0 | AW8: =+U8-AV8 -> 0
A9: 0073.PROGRAMA PARA LA GENERACION DEL EMPLEO SOCIAL INCLUSIVO - TRABAJA PERU | B9: 00 | C9: 01. PIA 2026 | D9: 3000001.ACCIONES COMUNES | E9: 5000276.GESTION DEL PROGRAMA | F9: 0047173.GESTION DEL PROGRAMA | G9: AOI00106600144. GESTIÓN OPERATIVA - UT AMAZONAS | H9: OTROS BIENES | I9: NO RESTRINGIDA | J9: UFAF | K9: UFAF | L9: UT AMAZONAS | M9: 0001. UT AMAZONAS | N9: 0001 | O9: UT AMAZONAS | P9: 5-23.BIENES Y SERVICIOS | Q9: 23 1 59999. OTROS | R9: 23 1 59999 | S9: OTROS | T9: 0 | U9: 7900 | X9: 7900 | Y9: =+IFERROR(X9/U9,0) -> 1 | Z9: =+U9-X9 -> 0 | AB9: 7900 | AC9: 0 | AD9: 5106.4 | AF9: 5106.4 | AG9: =+IFERROR(AF9/U9,0) -> 0.64637975 | AH9: =+Tabla1[[#This Row],[PIM]]-Tabla1[[#This Row],[DEVENGADO2]] -> 2793.6 | AI9: 500 | AJ9: 0 | AK9: 95.8 | AL9: 1386.6 | AM9: 745 | AN9: 1386 | AO9: 993 | AP9: 0 | AQ9: 718.18182 | AR9: 718.18182 | AS9: 718.18182 | AT9: 639.05455 | AU9: 0 | AV9: =+SUM(AI9:AU9) -> 7900 | AW9: =+U9-AV9 -> 0
A10: 0073.PROGRAMA PARA LA GENERACION DEL EMPLEO SOCIAL INCLUSIVO - TRABAJA PERU | B10: 00 | C10: 01. PIA 2026 | D10: 3000001.ACCIONES COMUNES | E10: 5000276.GESTION DEL PROGRAMA | F10: 0047173.GESTION DEL PROGRAMA | G10: AOI00106600144. GESTIÓN OPERATIVA - UT AMAZONAS | H10: OTROS BIENES | I10: NO RESTRINGIDA | J10: UFAF | K10: UFAF | L10: UT AMAZONAS | M10: 0001. UT AMAZONAS | N10: 0001 | O10: UT AMAZONAS | P10: 5-23.BIENES Y SERVICIOS | Q10: 23 1 6 1 1. DE VEHICULOS | R10: 23 1 6 1 1 | S10: DE VEHICULOS | T10: 545 | U10: 0 | X10: 0 | Y10: =+IFERROR(X10/U10,0) -> 0 | Z10: =+U10-X10 -> 0 | AB10: 0 | AC10: 0 | AD10: 0 | AF10: 0 | AG10: =+IFERROR(AF10/U10,0) -> 0 | AH10: =+Tabla1[[#This Row],[PIM]]-Tabla1[[#This Row],[DEVENGADO2]] -> 0 | AI10: 0 | AJ10: 0 | AK10: 0 | AL10: 0 | AM10: 0 | AN10: 0 | AO10: 0 | AP10: 0 | AQ10: 0 | AR10: 0 | AS10: 0 | AT10: 0 | AU10: 0 | AV10: =+SUM(AI10:AU10) -> 0 | AW10: =+U10-AV10 -> 0
A11: 0073.PROGRAMA PARA LA GENERACION DEL EMPLEO SOCIAL INCLUSIVO - TRABAJA PERU | B11: 00 | C11: 01. PIA 2026 | D11: 3000001.ACCIONES COMUNES | E11: 5000276.GESTION DEL PROGRAMA | F11: 0047173.GESTION DEL PROGRAMA | G11: AOI00106600144. GESTIÓN OPERATIVA - UT AMAZONAS | H11: PASAJES Y VIATICOS | I11: NO RESTRINGIDA | J11: UFAF | K11: UFAF | L11: UT AMAZONAS | M11: 0001. UT AMAZONAS | N11: 0001 | O11: UT AMAZONAS | P11: 5-23.BIENES Y SERVICIOS | Q11: 23 2 1 2 1. PASAJES Y GASTOS DE TRANSPORTE | R11: 23 2 1 2 1 | S11: PASAJES Y GASTOS DE TRANSPORTE | T11: 2000 | U11: 4600 | X11: 4600 | Y11: =+IFERROR(X11/U11,0) -> 1 | Z11: =+U11-X11 -> 0 | AB11: 4600 | AC11: 0 | AD11: 4570 | AF11: 4570 | AG11: =+IFERROR(AF11/U11,0) -> 0.99347826 | AH11: =+Tabla1[[#This Row],[PIM]]-Tabla1[[#This Row],[DEVENGADO2]] -> 30 | AI11: 0 | AJ11: 2300 | AK11: 400 | AL11: 0 | AM11: 1550 | AN11: 0 | AO11: 320 | AP11: 0 | AQ11: 0 | AR11: 0 | AS11: 0 | AT11: 0 | AU11: 30 | AV11: =+SUM(AI11:AU11) -> 4600 | AW11: =+U11-AV11 -> 0
A12: 0073.PROGRAMA PARA LA GENERACION DEL EMPLEO SOCIAL INCLUSIVO - TRABAJA PERU | B12: 00 | C12: 01. PIA 2026 | D12: 3000001.ACCIONES COMUNES | E12: 5000276.GESTION DEL PROGRAMA | F12: 0047173.GESTION DEL PROGRAMA | G12: AOI00106600144. GESTIÓN OPERATIVA - UT AMAZONAS | H12: PASAJES Y VIATICOS | I12: NO RESTRINGIDA | J12: UFAF | K12: UFAF | L12: UT AMAZONAS | M12: 0001. UT AMAZONAS | N12: 0001 | O12: UT AMAZONAS | P12: 5-23.BIENES Y SERVICIOS | Q12: 23 2 1 2 2. VIATICOS Y ASIGNACIONES POR COMISION DE SERVICIO | R12: 23 2 1 2 2 | S12: VIATICOS Y ASIGNACIONES POR COMISION DE SERVICIO | T12: 0 | U12: 3700 | X12: 3700 | Y12: =+IFERROR(X12/U12,0) -> 1 | Z12: =+U12-X12 -> 0 | AB12: 3700 | AC12: 0 | AD12: 983 | AF12: 983 | AG12: =+IFERROR(AF12/U12,0) -> 0.26567568 | AH12: =+Tabla1[[#This Row],[PIM]]-Tabla1[[#This Row],[DEVENGADO2]] -> 2717 | AI12: 0 | AJ12: 290 | AK12: 70 | AL12: 65 | AM12: 493 | AN12: 65 | AO12: 0 | AP12: 336.36364 | AQ12: 336.36364 | AR12: 336.36364 | AS12: 336.36364 | AT12: 336.36364 | AU12: 1035.1818 | AV12: =+SUM(AI12:AU12) -> 3700 | AW12: =+U12-AV12 -> 0
A13: 0073.PROGRAMA PARA LA GENERACION DEL EMPLEO SOCIAL INCLUSIVO - TRABAJA PERU | B13: 00 | C13: 01. PIA 2026 | D13: 3000001.ACCIONES COMUNES | E13: 5000276.GESTION DEL PROGRAMA | F13: 0047173.GESTION DEL PROGRAMA | G13: AOI00106600144. GESTIÓN OPERATIVA - UT AMAZONAS | H13: OTROS SERVICIOS | I13: NO RESTRINGIDA | J13: UFAF | K13: UFAF | L13: UT AMAZONAS | M13: 0001. UT AMAZONAS | N13: 0001 | O13: UT AMAZONAS | P13: 5-23.BIENES Y SERVICIOS | Q13: 23 2 1 299. OTROS GASTOS | R13: 23 2 1 299 | S13: OTROS GASTOS | T13: 0 | U13: 100 | X13: 100 | Y13: =+IFERROR(X13/U13,0) -> 1 | Z13: =+U13-X13 -> 0 | AB13: 100 | AC13: 0 | AD13: 26.1 | AF13: 26.1 | AG13: =+IFERROR(AF13/U13,0) -> 0.261 | AH13: =+Tabla1[[#This Row],[PIM]]-Tabla1[[#This Row],[DEVENGADO2]] -> 73.9 | AI13: 0 | AJ13: 0 | AK13: 0 | AL13: 0 | AM13: 8.7 | AN13: 8.7 | AO13: 8.7 | AP13: 0 | AQ13: 9.0909091 | AR13: 9.0909091 | AS13: 9.0909091 | AT13: 9.0909091 | AU13: 37.536364 | AV13: =+SUM(AI13:AU13) -> 100 | AW13: =+U13-AV13 -> 0
A14: 0073.PROGRAMA PARA LA GENERACION DEL EMPLEO SOCIAL INCLUSIVO - TRABAJA PERU | B14: 00 | C14: 01. PIA 2026 | D14: 3000001.ACCIONES COMUNES | E14: 5000276.GESTION DEL PROGRAMA | F14: 0047173.GESTION DEL PROGRAMA | G14: AOI00106600144. GESTIÓN OPERATIVA - UT AMAZONAS | H14: SERVICIOS DE LUZ, AGUA, INTERNET, TELF. FJA | I14: RESTRINGIDA | J14: UFAF | K14: UFAF | L14: UT AMAZONAS | M14: 0001. UT AMAZONAS | N14: 0001 | O14: UT AMAZONAS | P14: 5-23.BIENES Y SERVICIOS | Q14: 23 2 2 2 3. SERVICIO DE INTERNET | R14: 23 2 2 2 3 | S14: SERVICIO DE INTERNET | T14: 6000 | U14: 6000 | X14: 3150 | Y14: =+IFERROR(X14/U14,0) -> 0.525 | Z14: =+U14-X14 -> 2850 | AB14: 3150 | AC14: 2850 | AD14: 3150 | AF14: 3150 | AG14: =+IFERROR(AF14/U14,0) -> 0.525 | AH14: =+Tabla1[[#This Row],[PIM]]-Tabla1[[#This Row],[DEVENGADO2]] -> 2850 | AI14: 450 | AJ14: 450 | AK14: 450 | AL14: 450 | AM14: 450 | AN14: 450 | AO14: 450 | AP14: 0 | AQ14: 516.66667 | AR14: 516.66667 | AS14: 516.66667 | AT14: 516.66667 | AU14: 783.33333 | AV14: =+SUM(AI14:AU14) -> 6000 | AW14: =+U14-AV14 -> 0
A15: 0073.PROGRAMA PARA LA GENERACION DEL EMPLEO SOCIAL INCLUSIVO - TRABAJA PERU | B15: 00 | C15: 01. PIA 2026 | D15: 3000001.ACCIONES COMUNES | E15: 5000276.GESTION DEL PROGRAMA | F15: 0047173.GESTION DEL PROGRAMA | G15: AOI00106600144. GESTIÓN OPERATIVA - UT AMAZONAS | H15: SERVICIO DE MENSAJERIA | I15: NO RESTRINGIDA | J15: UFAF | K15: UFAF | L15: UT AMAZONAS | M15: 0001. UT AMAZONAS | N15: 0001 | O15: UT AMAZONAS | P15: 5-23.BIENES Y SERVICIOS | Q15: 23 2 2 3 1. CORREOS Y SERVICIOS DE MENSAJERIA | R15: 23 2 2 3 1 | S15: CORREOS Y SERVICIOS DE MENSAJERIA | T15: 0 | U15: 1600 | X15: 1600 | Y15: =+IFERROR(X15/U15,0) -> 1 | Z15: =+U15-X15 -> 0 | AB15: 1600 | AC15: 0 | AD15: 0 | AF15: 0 | AG15: =+IFERROR(AF15/U15,0) -> 0 | AH15: =+Tabla1[[#This Row],[PIM]]-Tabla1[[#This Row],[DEVENGADO2]] -> 1600 | AI15: 0 | AJ15: 0 | AK15: 0 | AL15: 0 | AM15: 0 | AN15: 0 | AO15: 0 | AP15: 145.45455 | AQ15: 145.45455 | AR15: 145.45455 | AS15: 145.45455 | AT15: 145.45455 | AU15: 872.72727 | AV15: =+SUM(AI15:AU15) -> 1600 | AW15: =+U15-AV15 -> 0
A16: 0073.PROGRAMA PARA LA GENERACION DEL EMPLEO SOCIAL INCLUSIVO - TRABAJA PERU | B16: 00 | C16: 01. PIA 2026 | D16: 3000001.ACCIONES COMUNES | E16: 5000276.GESTION DEL PROGRAMA | F16: 0047173.GESTION DEL PROGRAMA | G16: AOI00106600144. GESTIÓN OPERATIVA - UT AMAZONAS | H16: MANTENIMIENOT DE VEHICULOS | I16: NO RESTRINGIDA | J16: UFAF | K16: UFAF | L16: UT AMAZONAS | M16: 0001. UT AMAZONAS | N16: 0001 | O16: UT AMAZONAS | P16: 5-23.BIENES Y SERVICIOS | Q16: 23 2 4 5 1. DE VEHICULOS | R16: 23 2 4 5 1 | S16: DE VEHICULOS | T16: 8000 | U16: 520 | X16: 520 | Y16: =+IFERROR(X16/U16,0) -> 1 | Z16: =+U16-X16 -> 0 | AB16: 520 | AC16: 0 | AD16: 520 | AF16: 520 | AG16: =+IFERROR(AF16/U16,0) -> 1 | AH16: =+Tabla1[[#This Row],[PIM]]-Tabla1[[#This Row],[DEVENGADO2]] -> 0 | AI16: 0 | AJ16: 0 | AK16: 0 | AL16: 520 | AM16: 0 | AN16: 0 | AO16: 0 | AP16: 0 | AQ16: 0 | AR16: 0 | AS16: 0 | AT16: 0 | AU16: 0 | AV16: =+SUM(AI16:AU16) -> 520 | AW16: =+U16-AV16 -> 0
... A346: 0073.PROGRAMA PARA LA GENERACION DEL EMPLEO SOCIAL INCLUSIVO - TRABAJA PERU | B346: 00 | C346: 01. PIA 2026 | D346: 3000001.ACCIONES COMUNES | E346: 5000276.GESTION DEL PROGRAMA | F346: 0047173.GESTION DEL PROGRAMA | G346: AOI00106600086. PROGRAMACIÓN, FORMULACIÓN, APROBACIÓN, EJECUCIÓN Y EVALUACIÓN DEL PROCESO PRESUPUESTARIO DEL PROGRAMA | H346: SERVICIOS DIVERSOS | I346: RESTRINGIDA | J346: UFPP | K346: UFPP | L346: UFPP | M346: 0017. UFPP | N346: 0017 | O346: UFPP | P346: 5-23.BIENES Y SERVICIOS | Q346: 23 2 71199. SERVICIOS DIVERSOS | R346: 23 2 71199 | S346: SERVICIOS DIVERSOS | T346: 619300 | U346: 418922 | X346: 418922 | Y346: =+IFERROR(X346/U346,0) -> 1 | Z346: =+U346-X346 -> 0 | AB346: 418922 | AC346: 0 | AD346: 0 | AF346: 0 | AG346: =+IFERROR(AF346/U346,0) -> 0 | AH346: =+Tabla1[[#This Row],[PIM]]-Tabla1[[#This Row],[DEVENGADO2]] -> 418922 | AI346: 0 | AJ346: 0 | AK346: 0 | AL346: 0 | AM346: 0 | AN346: 0 | AO346: 0 | AP346: 0 | AQ346: 10000 | AR346: 0 | AS346: 0 | AT346: 0 | AU346: 408922 | AV346: =+SUM(AI346:AU346) -> 418922 | AW346: =+U346-AV346 -> 0
A347: 0073.PROGRAMA PARA LA GENERACION DEL EMPLEO SOCIAL INCLUSIVO - TRABAJA PERU | C347: 01. PIA 2026 | D347: 3000001.ACCIONES COMUNES | E347: 5000276.GESTION DEL PROGRAMA | F347: 0047173.GESTION DEL PROGRAMA | G347: AOI00106600086. PROGRAMACIÓN, FORMULACIÓN, APROBACIÓN, EJECUCIÓN Y EVALUACIÓN DEL PROCESO PRESUPUESTARIO DEL PROGRAMA | H347: LOCADORES | I347: NO RESTRINGIDA | J347: UFPP | K347: UFPP | L347: UFPP | M347: 0017. UFPP | N347: 0017 | O347: UFPP | P347: 5-23.BIENES Y SERVICIOS | Q347: 23 2 9 1 1. LOCACIÓN DE SERVICIOS REALIZADOS POR PERSONA NATURAL | R347: 23 2 9 1 1 | S347: LOCACIÓN DE SERVICIOS REALIZADOS POR PERSONA NATURAL | T347: 1106019 | U347: 24500 | X347: 24500 | Y347: =+IFERROR(X347/U347,0) -> 1 | Z347: =+U347-X347 -> 0 | AB347: 24500 | AC347: 0 | AD347: 24500 | AF347: 24500 | AG347: =+IFERROR(AF347/U347,0) -> 1 | AH347: =+Tabla1[[#This Row],[PIM]]-Tabla1[[#This Row],[DEVENGADO2]] -> 0 | AI347: 0 | AJ347: 0 | AK347: 12000 | AL347: 6000 | AM347: 0 | AN347: 6500 | AO347: 0 | AP347: 0 | AQ347: 0 | AR347: 0 | AS347: 0 | AT347: 0 | AU347: 0 | AV347: =+SUM(AI347:AU347) -> 24500 | AW347: =+U347-AV347 -> 0
A348: 0073.PROGRAMA PARA LA GENERACION DEL EMPLEO SOCIAL INCLUSIVO - TRABAJA PERU | B348: 00 | C348: 01. PIA 2026 | D348: 3000001.ACCIONES COMUNES | E348: 5000276.GESTION DEL PROGRAMA | F348: 0047173.GESTION DEL PROGRAMA | G348: AOI00106600086. PROGRAMACIÓN, FORMULACIÓN, APROBACIÓN, EJECUCIÓN Y EVALUACIÓN DEL PROCESO PRESUPUESTARIO DEL PROGRAMA | H348: FINANCIAMIENTO DE AII | I348: NO RESTRINGIDA | J348: UFPP | K348: UFPP | L348: UFPP | M348: 0017. UFPP | N348: 0017 | O348: UFPP | P348: 5-24.DONACIONES Y TRANSFERENCIAS | Q348: 24 1 3 1 3. A OTRAS UNIDADES DEL GOBIERNO LOCAL | R348: 24 1 3 1 3 | S348: A OTRAS UNIDADES DEL GOBIERNO LOCAL | T348: 0 | U348: 2401572 | X348: 0 | Y348: =+IFERROR(X348/U348,0) -> 0 | Z348: =+U348-X348 -> 2401572 | AB348: 0 | AC348: 2401572 | AD348: 0 | AF348: 0 | AG348: =+IFERROR(AF348/U348,0) -> 0 | AH348: =+Tabla1[[#This Row],[PIM]]-Tabla1[[#This Row],[DEVENGADO2]] -> 2401572 | AI348: 0 | AJ348: 0 | AK348: 0 | AL348: 0 | AM348: 0 | AN348: 0 | AO348: 0 | AP348: 0 | AQ348: 0 | AR348: 2401572 | AS348: 0 | AT348: 0 | AU348: 0 | AV348: =+SUM(AI348:AU348) -> 2401572 | AW348: =+U348-AV348 -> 0
A349: 0073.PROGRAMA PARA LA GENERACION DEL EMPLEO SOCIAL INCLUSIVO - TRABAJA PERU | B349: 00 | C349: 01. PIA 2026 | D349: 3000001.ACCIONES COMUNES | E349: 5000276.GESTION DEL PROGRAMA | F349: 0047173.GESTION DEL PROGRAMA | G349: AOI00106600093. PLANIFICACIÓN Y GESTIÓN ESTRATEGICA DE RECURSOS HUMANOS | H349: PERSONAL DL 728 | I349: RESTRINGIDA | J349: UFRH | K349: UFRH | L349: UFRH | M349: 0018. UFRH | N349: 0018 | O349: UFRH | P349: 5-21.PERSONAL Y OBLIGACIONES SOCIALES | Q349: 21 1 9 1 1. GRATIFICACIONES | R349: 21 1 9 1 1 | S349: GRATIFICACIONES | T349: 0 | U349: 80000 | X349: 80000 | Y349: =+IFERROR(X349/U349,0) -> 1 | Z349: =+U349-X349 -> 0 | AB349: 80000 | AC349: 0 | AD349: 66288.71 | AF349: 66288.71 | AG349: =+IFERROR(AF349/U349,0) -> 0.82860888 | AH349: =+Tabla1[[#This Row],[PIM]]-Tabla1[[#This Row],[DEVENGADO2]] -> 13711.29 | AI349: 0 | AJ349: 0 | AK349: 0 | AL349: 0 | AM349: 0 | AN349: 0 | AO349: 66288.71 | AP349: 0 | AQ349: 0 | AR349: 0 | AS349: 0 | AT349: 0 | AU349: 13711.29 | AV349: =+SUM(AI349:AU349) -> 80000 | AW349: =+U349-AV349 -> 0
A350: 0073.PROGRAMA PARA LA GENERACION DEL EMPLEO SOCIAL INCLUSIVO - TRABAJA PERU | B350: 00 | C350: 01. PIA 2026 | D350: 3000001.ACCIONES COMUNES | E350: 5000276.GESTION DEL PROGRAMA | F350: 0047173.GESTION DEL PROGRAMA | G350: AOI00106600093. PLANIFICACIÓN Y GESTIÓN ESTRATEGICA DE RECURSOS HUMANOS | H350: CAS | I350: RESTRINGIDA | J350: UFRH | K350: UFRH | L350: UFRH | M350: 0018. UFRH | N350: 0018 | O350: UFRH | P350: 5-21.PERSONAL Y OBLIGACIONES SOCIALES | Q350: 21 1 9 1 4. AGUINALDOS DE CONTRATO ADMINISTRATIVO DE SERVICIOS | R350: 21 1 9 1 4 | S350: AGUINALDOS DE CONTRATO ADMINISTRATIVO DE SERVICIOS | T350: 6600 | U350: 6300 | X350: 6300 | Y350: =+IFERROR(X350/U350,0) -> 1 | Z350: =+U350-X350 -> 0 | AB350: 6300 | AC350: 0 | AD350: 0 | AF350: 0 | AG350: =+IFERROR(AF350/U350,0) -> 0 | AH350: =+Tabla1[[#This Row],[PIM]]-Tabla1[[#This Row],[DEVENGADO2]] -> 6300 | AI350: 0 | AJ350: 0 | AK350: 0 | AL350: 0 | AM350: 0 | AN350: 0 | AO350: 0 | AP350: 3300 | AQ350: 0 | AR350: 0 | AS350: 0 | AT350: 0 | AU350: 3000 | AV350: =+SUM(AI350:AU350) -> 6300 | AW350: =+U350-AV350 -> 0
A351: 0073.PROGRAMA PARA LA GENERACION DEL EMPLEO SOCIAL INCLUSIVO - TRABAJA PERU | B351: 00 | C351: 01. PIA 2026 | D351: 3000001.ACCIONES COMUNES | E351: 5000276.GESTION DEL PROGRAMA | F351: 0047173.GESTION DEL PROGRAMA | G351: AOI00106600093. PLANIFICACIÓN Y GESTIÓN ESTRATEGICA DE RECURSOS HUMANOS | H351: CAS | I351: RESTRINGIDA | J351: UFRH | K351: UFRH | L351: UFRH | M351: 0018. UFRH | N351: 0018 | O351: UFRH | P351: 5-21.PERSONAL Y OBLIGACIONES SOCIALES | Q351: 21 1 9 314. OTROS BONOS EXTRAORDINARIOS PERSONAL CAS | R351: 21 1 9 314 | S351: OTROS BONOS EXTRAORDINARIOS PERSONAL CAS | T351: 0 | U351: 18700 | X351: 16900 | Y351: =+IFERROR(X351/U351,0) -> 0.90374332 | Z351: =+U351-X351 -> 1800 | AB351: 16900 | AC351: 1800 | AD351: 16900 | AF351: 16900 | AG351: =+IFERROR(AF351/U351,0) -> 0.90374332 | AH351: =+Tabla1[[#This Row],[PIM]]-Tabla1[[#This Row],[DEVENGADO2]] -> 1800 | AI351: 16500 | AJ351: 400 | AK351: 0 | AL351: 0 | AM351: 0 | AN351: 0 | AO351: 0 | AP351: 0 | AQ351: 0 | AR351: 0 | AS351: 0 | AT351: 0 | AU351: 1800 | AV351: =+SUM(AI351:AU351) -> 18700 | AW351: =+U351-AV351 -> 0
A352: 0073.PROGRAMA PARA LA GENERACION DEL EMPLEO SOCIAL INCLUSIVO - TRABAJA PERU | B352: 00 | C352: 01. PIA 2026 | D352: 3000001.ACCIONES COMUNES | E352: 5000276.GESTION DEL PROGRAMA | F352: 0047173.GESTION DEL PROGRAMA | G352: AOI00106600093. PLANIFICACIÓN Y GESTIÓN ESTRATEGICA DE RECURSOS HUMANOS | H352: CAS | I352: RESTRINGIDA | J352: UFRH | K352: UFRH | L352: UFRH | M352: 0018. UFRH | N352: 0018 | O352: UFRH | P352: 5-21.PERSONAL Y OBLIGACIONES SOCIALES | Q352: 21 113 1 1. CONTRATO ADMINISTRATIVO DE SERVICIOS - INDETERMINADO | R352: 21 113 1 1 | S352: CONTRATO ADMINISTRATIVO DE SERVICIOS - INDETERMINADO | T352: 387851 | U352: 374552 | X352: 374552 | Y352: =+IFERROR(X352/U352,0) -> 1 | Z352: =+U352-X352 -> 0 | AB352: 374552 | AC352: 0 | AD352: 210162.03 | AF352: 210162.03 | AG352: =+IFERROR(AF352/U352,0) -> 0.56110241 | AH352: =+Tabla1[[#This Row],[PIM]]-Tabla1[[#This Row],[DEVENGADO2]] -> 164389.97 | AI352: 13653.94 | AJ352: 32747.31 | AK352: 32762.17 | AL352: 32728.12 | AM352: 32772.57 | AN352: 32748.92 | AO352: 32749 | AP352: 0 | AQ352: 32320.95 | AR352: 32320.95 | AS352: 32320.95 | AT352: 32320.95 | AU352: 35106.17 | AV352: =+SUM(AI352:AU352) -> 374552 | AW352: =+U352-AV352 -> 0
A353: 0073.PROGRAMA PARA LA GENERACION DEL EMPLEO SOCIAL INCLUSIVO - TRABAJA PERU | B353: 00 | C353: 01. PIA 2026 | D353: 3000001.ACCIONES COMUNES | E353: 5000276.GESTION DEL PROGRAMA | F353: 0047173.GESTION DEL PROGRAMA | G353: AOI00106600093. PLANIFICACIÓN Y GESTIÓN ESTRATEGICA DE RECURSOS HUMANOS | H353: CAS | I353: RESTRINGIDA | J353: UFRH | K353: UFRH | L353: UFRH | M353: 0018. UFRH | N353: 0018 | O353: UFRH | P353: 5-21.PERSONAL Y OBLIGACIONES SOCIALES | Q353: 21 113 1 2. CONTRATO ADMINISTRATIVO DE SERVICIOS - TRANSITORIO | R353: 21 113 1 2 | S353: CONTRATO ADMINISTRATIVO DE SERVICIOS - TRANSITORIO | T353: 589077 | U353: 826737 | X353: 826737 | Y353: =+IFERROR(X353/U353,0) -> 1 | Z353: =+U353-X353 -> 0 | AB353: 826737 | AC353: 0 | AD353: 290890.44 | AF353: 290890.44 | AG353: =+IFERROR(AF353/U353,0) -> 0.35185366 | AH353: =+Tabla1[[#This Row],[PIM]]-Tabla1[[#This Row],[DEVENGADO2]] -> 535846.56 | AI353: 56612.3 | AJ353: 34312.95 | AK353: 34373.67 | AL353: 41482.11 | AM353: 41458.16 | AN353: 41382.43 | AO353: 41268.82 | AP353: 0 | AQ353: 49085.14 | AR353: 49085.14 | AS353: 49085.14 | AT353: 49085.14 | AU353: 339506 | AV353: =+SUM(AI353:AU353) -> 826737 | AW353: =+U353-AV353 -> 0
A354: 0073.PROGRAMA PARA LA GENERACION DEL EMPLEO SOCIAL INCLUSIVO - TRABAJA PERU | B354: 00 | C354: 01. PIA 2026 | D354: 3000001.ACCIONES COMUNES | E354: 5000276.GESTION DEL PROGRAMA | F354: 0047173.GESTION DEL PROGRAMA | G354: AOI00106600093. PLANIFICACIÓN Y GESTIÓN ESTRATEGICA DE RECURSOS HUMANOS | H354: CAS | I354: RESTRINGIDA | J354: UFRH | K354: UFRH | L354: UFRH | M354: 0018. UFRH | N354: 0018 | O354: UFRH | P354: 5-21.PERSONAL Y OBLIGACIONES SOCIALES | Q354: 21 3 1 115. CONTRIBUCIONES A ESSALUD DE CONTRATO ADMINISTRATIVO DE SERVICIOS | R354: 21 3 1 115 | S354: CONTRIBUCIONES A ESSALUD DE CONTRATO ADMINISTRATIVO DE SERVICIOS | T354: 30360 | U354: 34749 | X354: 34749 | Y354: =+IFERROR(X354/U354,0) -> 1 | Z354: =+U354-X354 -> 0 | AB354: 34749 | AC354: 0 | AD354: 15363.39 | AF354: 15363.39 | AG354: =+IFERROR(AF354/U354,0) -> 0.44212467 | AH354: =+Tabla1[[#This Row],[PIM]]-Tabla1[[#This Row],[DEVENGADO2]] -> 19385.61 | AI354: 2227.5 | AJ354: 2004.75 | AK354: 2004.75 | AL354: 2227.5 | AM354: 2227.5 | AN354: 2227.5 | AO354: 2443.89 | AP354: 0 | AQ354: 2530 | AR354: 2530 | AS354: 2530 | AT354: 2530 | AU354: 9265.61 | AV354: =+SUM(AI354:AU354) -> 34749 | AW354: =+U354-AV354 -> 0
A355: 0073.PROGRAMA PARA LA GENERACION DEL EMPLEO SOCIAL INCLUSIVO - TRABAJA PERU | B355: 00 | C355: 01. PIA 2026 | D355: 3000001.ACCIONES COMUNES | E355: 5000276.GESTION DEL PROGRAMA | F355: 0047173.GESTION DEL PROGRAMA | G355: AOI00106600093. PLANIFICACIÓN Y GESTIÓN ESTRATEGICA DE RECURSOS HUMANOS | H355: CAS | I355: NO RESTRINGIDA | J355: UFRH | K355: UFRH | L355: UFRH | M355: 0018. UFRH | N355: 0018 | O355: UFRH | P355: 5-21.PERSONAL Y OBLIGACIONES SOCIALES | Q355: 21 4 1 1 7. VACACIONES TRUNCAS PERSONAL CAS | R355: 21 4 1 1 7 | S355: VACACIONES TRUNCAS PERSONAL CAS | T355: 0 | U355: 14710 | X355: 14710 | Y355: =+IFERROR(X355/U355,0) -> 1 | Z355: =+U355-X355 -> 0 | AB355: 14710 | AC355: 0 | AD355: 14707.94 | AF355: 14707.94 | AG355: =+IFERROR(AF355/U355,0) -> 0.99985996 | AH355: =+Tabla1[[#This Row],[PIM]]-Tabla1[[#This Row],[DEVENGADO2]] -> 2.06 | AI355: 6550.99 | AJ355: 8156.95 | AK355: 0 | AL355: 0 | AM355: 0 | AN355: 0 | AO355: 0 | AP355: 0 | AQ355: 0 | AR355: 0 | AS355: 0 | AT355: 0 | AU355: 2.06 | AV355: =+SUM(AI355:AU355) -> 14710 | AW355: =+U355-AV355 -> 0
A356: 0073.PROGRAMA PARA LA GENERACION DEL EMPLEO SOCIAL INCLUSIVO - TRABAJA PERU | B356: 00 | C356: 01. PIA 2026 | D356: 3000001.ACCIONES COMUNES | E356: 5000276.GESTION DEL PROGRAMA | F356: 0047173.GESTION DEL PROGRAMA | G356: AOI00106600093. PLANIFICACIÓN Y GESTIÓN ESTRATEGICA DE RECURSOS HUMANOS | H356: AGUA DE MESA | I356: NO RESTRINGIDA | J356: UFRH | K356: UFRH | L356: UFRH | M356: 0018. UFRH | N356: 0018 | O356: UFRH | P356: 5-23.BIENES Y SERVICIOS | Q356: 23 1 1 1 1. ALIMENTOS Y BEBIDAS PARA CONSUMO HUMANO | R356: 23 1 1 1 1 | S356: ALIMENTOS Y BEBIDAS PARA CONSUMO HUMANO | T356: 1400 | U356: 1400 | X356: 0 | Y356: =+IFERROR(X356/U356,0) -> 0 | Z356: =+U356-X356 -> 1400 | AB356: 0 | AC356: 1400 | AD356: 0 | AF356: 0 | AG356: =+IFERROR(AF356/U356,0) -> 0 | AH356: =+Tabla1[[#This Row],[PIM]]-Tabla1[[#This Row],[DEVENGADO2]] -> 1400 | AI356: 0 | AJ356: 0 | AK356: 0 | AL356: 0 | AM356: 0 | AN356: 0 | AO356: 0 | AP356: 0 | AQ356: 0 | AR356: 0 | AS356: 0 | AT356: 0 | AU356: 1400 | AV356: =+SUM(AI356:AU356) -> 1400 | AW356: =+U356-AV356 -> 0
A357: 0073.PROGRAMA PARA LA GENERACION DEL EMPLEO SOCIAL INCLUSIVO - TRABAJA PERU | B357: 00 | C357: 01. PIA 2026 | D357: 3000001.ACCIONES COMUNES | E357: 5000276.GESTION DEL PROGRAMA | F357: 0047173.GESTION DEL PROGRAMA | G357: AOI00106600093. PLANIFICACIÓN Y GESTIÓN ESTRATEGICA DE RECURSOS HUMANOS | H357: VESTUARIO | I357: NO RESTRINGIDA | J357: UFRH | K357: UFRH | L357: UFRH | M357: 0018. UFRH | N357: 0018 | O357: UFRH | P357: 5-23.BIENES Y SERVICIOS | Q357: 23 1 2 1 1. VESTUARIO, ACCESORIOS Y PRENDAS DIVERSAS | R357: 23 1 2 1 1 | S357: VESTUARIO, ACCESORIOS Y PRENDAS DIVERSAS | T357: 8380 | U357: 0 | X357: 0 | Y357: =+IFERROR(X357/U357,0) -> 0 | Z357: =+U357-X357 -> 0 | AB357: 0 | AC357: 0 | AD357: 0 | AF357: 0 | AG357: =+IFERROR(AF357/U357,0) -> 0 | AH357: =+Tabla1[[#This Row],[PIM]]-Tabla1[[#This Row],[DEVENGADO2]] -> 0 | AI357: 0 | AJ357: 0 | AK357: 0 | AL357: 0 | AM357: 0 | AN357: 0 | AO357: 0 | AP357: 0 | AQ357: 0 | AR357: 0 | AS357: 0 | AT357: 0 | AU357: 0 | AV357: =+SUM(AI357:AU357) -> 0 | AW357: =+U357-AV357 -> 0
A358: 0073.PROGRAMA PARA LA GENERACION DEL EMPLEO SOCIAL INCLUSIVO - TRABAJA PERU | B358: 00 | C358: 01. PIA 2026 | D358: 3000001.ACCIONES COMUNES | E358: 5000276.GESTION DEL PROGRAMA | F358: 0047173.GESTION DEL PROGRAMA | G358: AOI00106600093. PLANIFICACIÓN Y GESTIÓN ESTRATEGICA DE RECURSOS HUMANOS | H358: OTROS BIENES | I358: NO RESTRINGIDA | J358: UFRH | K358: UFRH | L358: UFRH | M358: 0018. UFRH | N358: 0018 | O358: UFRH | P358: 5-23.BIENES Y SERVICIOS | Q358: 23 1 5 1 1. REPUESTOS Y ACCESORIOS | R358: 23 1 5 1 1 | S358: REPUESTOS Y ACCESORIOS | T358: 0 | U358: 0 | X358: 0 | Y358: =+IFERROR(X358/U358,0) -> 0 | Z358: =+U358-X358 -> 0 | AB358: 0 | AC358: 0 | AD358: 0 | AF358: 0 | AG358: =+IFERROR(AF358/U358,0) -> 0 | AH358: =+Tabla1[[#This Row],[PIM]]-Tabla1[[#This Row],[DEVENGADO2]] -> 0 | AI358: 0 | AJ358: 0 | AK358: 0 | AL358: 0 | AM358: 0 | AN358: 0 | AO358: 0 | AP358: 0 | AQ358: 0 | AR358: 0 | AS358: 0 | AT358: 0 | AU358: 0 | AV358: =+SUM(AI358:AU358) -> 0 | AW358: =+U358-AV358 -> 0
A359: 0073.PROGRAMA PARA LA GENERACION DEL EMPLEO SOCIAL INCLUSIVO - TRABAJA PERU | B359: 00 | C359: 01. PIA 2026 | D359: 3000001.ACCIONES COMUNES | E359: 5000276.GESTION DEL PROGRAMA | F359: 0047173.GESTION DEL PROGRAMA | G359: AOI00106600093. PLANIFICACIÓN Y GESTIÓN ESTRATEGICA DE RECURSOS HUMANOS | H359: OTROS BIENES | I359: NO RESTRINGIDA | J359: UFRH | K359: UFRH | L359: UFRH | M359: 0018. UFRH | N359: 0018 | O359: UFRH | P359: 5-23.BIENES Y SERVICIOS | Q359: 23 1 5 3 1. ASEO, LIMPIEZA Y TOCADOR | R359: 23 1 5 3 1 | S359: ASEO, LIMPIEZA Y TOCADOR | T359: 3240 | U359: 0 | X359: 0 | Y359: =+IFERROR(X359/U359,0) -> 0 | Z359: =+U359-X359 -> 0 | AB359: 0 | AC359: 0 | AD359: 0 | AF359: 0 | AG359: =+IFERROR(AF359/U359,0) -> 0 | AH359: =+Tabla1[[#This Row],[PIM]]-Tabla1[[#This Row],[DEVENGADO2]] -> 0 | AI359: 0 | AJ359: 0 | AK359: 0 | AL359: 0 | AM359: 0 | AN359: 0 | AO359: 0 | AP359: 0 | AQ359: 0 | AR359: 0 | AS359: 0 | AT359: 0 | AU359: 0 | AV359: =+SUM(AI359:AU359) -> 0 | AW359: =+U359-AV359 -> 0
... A510: 0073.PROGRAMA PARA LA GENERACION DEL EMPLEO SOCIAL INCLUSIVO - TRABAJA PERU | B510: 00 | C510: 01. PIA 2026 | D510: 3000001.ACCIONES COMUNES | E510: 5000276.GESTION DEL PROGRAMA | F510: 0047173.GESTION DEL PROGRAMA | G510: AOI00106600163. GESTIÓN OPERATIVA - UT SAN MARTIN | H510: SERVICIOS DE LUZ, AGUA, INTERNET, TELF. FJA | I510: RESTRINGIDA | J510: UFAF | K510: UFAF | L510: UT SAN MARTIN | M510: 0027. UT SAN MARTIN | N510: 0027 | O510: UT SAN MARTIN | P510: 5-23.BIENES Y SERVICIOS | Q510: 23 2 2 2 3. SERVICIO DE INTERNET | R510: 23 2 2 2 3 | S510: SERVICIO DE INTERNET | T510: 1200 | U510: 3893 | X510: 3892.95 | Y510: =+IFERROR(X510/U510,0) -> 0.99998716 | Z510: =+U510-X510 -> 0.05 | AB510: 3892.95 | AC510: 0.05 | AD510: 3892.95 | AF510: 1892.95 | AG510: =+IFERROR(AF510/U510,0) -> 0.48624454 | AH510: =+Tabla1[[#This Row],[PIM]]-Tabla1[[#This Row],[DEVENGADO2]] -> 2000.05 | AI510: 0 | AJ510: 199.98 | AK510: 92.97 | AL510: 400 | AM510: 400 | AN510: 400 | AO510: 400 | AP510: 0 | AQ510: 400.00714 | AR510: 400.00714 | AS510: 400.00714 | AT510: 400.00714 | AU510: 400.02143 | AV510: =+SUM(AI510:AU510) -> 3893 | AW510: =+U510-AV510 -> 0
A511: 0073.PROGRAMA PARA LA GENERACION DEL EMPLEO SOCIAL INCLUSIVO - TRABAJA PERU | C511: 01. PIA 2026 | D511: 3000001.ACCIONES COMUNES | E511: 5000276.GESTION DEL PROGRAMA | F511: 0047173.GESTION DEL PROGRAMA | G511: AOI00106600163. GESTIÓN OPERATIVA - UT SAN MARTIN | H511: SERVICIO DE MENSAJERIA | I511: NO RESTRINGIDA | J511: UFAF | K511: UFAF | L511: UT SAN MARTIN | M511: 0027. UT SAN MARTIN | N511: 0027 | O511: UT SAN MARTIN | P511: 5-23.BIENES Y SERVICIOS | Q511: 23 2 2 3 1. CORREOS Y SERVICIOS DE MENSAJERIA | R511: 23 2 2 3 1 | S511: CORREOS Y SERVICIOS DE MENSAJERIA | T511: 0 | U511: 600 | X511: 600 | Y511: =+IFERROR(X511/U511,0) -> 1 | Z511: =+U511-X511 -> 0 | AB511: 600 | AC511: 0 | AD511: 150 | AF511: 150 | AG511: =+IFERROR(AF511/U511,0) -> 0.25 | AH511: =+Tabla1[[#This Row],[PIM]]-Tabla1[[#This Row],[DEVENGADO2]] -> 450 | AI511: 0 | AJ511: 0 | AK511: 0 | AL511: 122 | AM511: 0 | AN511: 28 | AO511: 0 | AP511: 54.545455 | AQ511: 54.545455 | AR511: 54.545455 | AS511: 54.545455 | AT511: 54.545455 | AU511: 177.27273 | AV511: =+SUM(AI511:AU511) -> 600 | AW511: =+U511-AV511 -> 0
A512: 0073.PROGRAMA PARA LA GENERACION DEL EMPLEO SOCIAL INCLUSIVO - TRABAJA PERU | C512: 01. PIA 2026 | D512: 3000001.ACCIONES COMUNES | E512: 5000276.GESTION DEL PROGRAMA | F512: 0047173.GESTION DEL PROGRAMA | G512: AOI00106600163. GESTIÓN OPERATIVA - UT SAN MARTIN | H512: MANTENIMIENOT DE VEHICULOS | I512: NO RESTRINGIDA | J512: UFAF | K512: UFAF | L512: UT SAN MARTIN | M512: 0027. UT SAN MARTIN | N512: 0027 | O512: UT SAN MARTIN | P512: 5-23.BIENES Y SERVICIOS | Q512: 23 2 4 5 1. DE VEHICULOS | R512: 23 2 4 5 1 | S512: DE VEHICULOS | T512: 7600 | U512: 3764 | X512: 3764 | Y512: =+IFERROR(X512/U512,0) -> 1 | Z512: =+U512-X512 -> 0 | AB512: 3764 | AC512: 0 | AD512: 3764 | AF512: 3764 | AG512: =+IFERROR(AF512/U512,0) -> 1 | AH512: =+Tabla1[[#This Row],[PIM]]-Tabla1[[#This Row],[DEVENGADO2]] -> 0 | AI512: 0 | AJ512: 1485.5 | AK512: 0 | AL512: 0 | AM512: 793 | AN512: 0 | AO512: 1485.5 | AP512: 0 | AQ512: 0 | AR512: 0 | AS512: 0 | AT512: 0 | AU512: 0 | AV512: =+SUM(AI512:AU512) -> 3764 | AW512: =+U512-AV512 -> 0
A513: 0073.PROGRAMA PARA LA GENERACION DEL EMPLEO SOCIAL INCLUSIVO - TRABAJA PERU | C513: 01. PIA 2026 | D513: 3000001.ACCIONES COMUNES | E513: 5000276.GESTION DEL PROGRAMA | F513: 0047173.GESTION DEL PROGRAMA | G513: AOI00106600163. GESTIÓN OPERATIVA - UT SAN MARTIN | H513: ALQUILER DE LOCAL | I513: NO RESTRINGIDA | J513: UFAF | K513: UFAF | L513: UT SAN MARTIN | M513: 0027. UT SAN MARTIN | N513: 0027 | O513: UT SAN MARTIN | P513: 5-23.BIENES Y SERVICIOS | Q513: 23 2 5 1 1. DE EDIFICIOS Y ESTRUCTURAS | R513: 23 2 5 1 1 | S513: DE EDIFICIOS Y ESTRUCTURAS | T513: 48000 | U513: 48000 | X513: 48000 | Y513: =+IFERROR(X513/U513,0) -> 1 | Z513: =+U513-X513 -> 0 | AB513: 48000 | AC513: 0 | AD513: 48000 | AF513: 24000 | AG513: =+IFERROR(AF513/U513,0) -> 0.5 | AH513: =+Tabla1[[#This Row],[PIM]]-Tabla1[[#This Row],[DEVENGADO2]] -> 24000 | AI513: 0 | AJ513: 4000 | AK513: 4000 | AL513: 4000 | AM513: 4000 | AN513: 4000 | AO513: 4000 | AP513: 0 | AQ513: 4800 | AR513: 4800 | AS513: 4800 | AT513: 4800 | AU513: 4800 | AV513: =+SUM(AI513:AU513) -> 48000 | AW513: =+U513-AV513 -> 0
A514: 0073.PROGRAMA PARA LA GENERACION DEL EMPLEO SOCIAL INCLUSIVO - TRABAJA PERU | C514: 01. PIA 2026 | D514: 3000001.ACCIONES COMUNES | E514: 5000276.GESTION DEL PROGRAMA | F514: 0047173.GESTION DEL PROGRAMA | G514: AOI00106600163. GESTIÓN OPERATIVA - UT SAN MARTIN | H514: OTROS SERVICIOS | I514: NO RESTRINGIDA | J514: UFAF | K514: UFAF | L514: UT SAN MARTIN | M514: 0027. UT SAN MARTIN | N514: 0027 | O514: UT SAN MARTIN | P514: 5-23.BIENES Y SERVICIOS | Q514: 23 2 711 2. TRANSPORTE Y TRASLADO DE CARGA, BIENES Y MATERIALES | R514: 23 2 711 2 | S514: TRANSPORTE Y TRASLADO DE CARGA, BIENES Y MATERIALES | T514: 0 | U514: 1000 | X514: 0 | Y514: =+IFERROR(X514/U514,0) -> 0 | Z514: =+U514-X514 -> 1000 | AB514: 0 | AC514: 1000 | AD514: 0 | AF514: 0 | AG514: =+IFERROR(AF514/U514,0) -> 0 | AH514: =+Tabla1[[#This Row],[PIM]]-Tabla1[[#This Row],[DEVENGADO2]] -> 1000 | AI514: 0 | AJ514: 0 | AK514: 0 | AL514: 0 | AM514: 0 | AN514: 0 | AO514: 0 | AP514: 0 | AQ514: 0 | AR514: 1000 | AS514: 0 | AT514: 0 | AU514: 0 | AV514: =+SUM(AI514:AU514) -> 1000 | AW514: =+U514-AV514 -> 0
A515: 0073.PROGRAMA PARA LA GENERACION DEL EMPLEO SOCIAL INCLUSIVO - TRABAJA PERU | C515: 01. PIA 2026 | D515: 3000001.ACCIONES COMUNES | E515: 5000276.GESTION DEL PROGRAMA | F515: 0047173.GESTION DEL PROGRAMA | G515: AOI00106600163. GESTIÓN OPERATIVA - UT SAN MARTIN | H515: SERVICIOS DIVERSOS | I515: RESTRINGIDA | J515: UFAF | K515: UFAF | L515: UT SAN MARTIN | M515: 0027. UT SAN MARTIN | N515: 0027 | O515: UT SAN MARTIN | P515: 5-23.BIENES Y SERVICIOS | Q515: 23 2 71199. SERVICIOS DIVERSOS | R515: 23 2 71199 | S515: SERVICIOS DIVERSOS | T515: 59600 | U515: 60034 | X515: 36534 | Y515: =+IFERROR(X515/U515,0) -> 0.60855515 | Z515: =+U515-X515 -> 23500 | AB515: 36534 | AC515: 23500 | AD515: 34546 | AF515: 25146 | AG515: =+IFERROR(AF515/U515,0) -> 0.41886264 | AH515: =+Tabla1[[#This Row],[PIM]]-Tabla1[[#This Row],[DEVENGADO2]] -> 34888 | AI515: 1000 | AJ515: 3234 | AK515: 4700 | AL515: 4752 | AM515: 3000 | AN515: 3760 | AO515: 4700 | AP515: 0 | AQ515: 5500 | AR515: 5500 | AS515: 5500 | AT515: 5500 | AU515: 12888 | AV515: =+SUM(AI515:AU515) -> 60034 | AW515: =+U515-AV515 -> 0
A516: 0073.PROGRAMA PARA LA GENERACION DEL EMPLEO SOCIAL INCLUSIVO - TRABAJA PERU | C516: 01. PIA 2026 | D516: 3000001.ACCIONES COMUNES | E516: 5000276.GESTION DEL PROGRAMA | F516: 0047173.GESTION DEL PROGRAMA | G516: AOI00106600163. GESTIÓN OPERATIVA - UT SAN MARTIN | H516: LOCADORES | I516: NO RESTRINGIDA | J516: UFAF | K516: UFAF | L516: UT SAN MARTIN | M516: 0027. UT SAN MARTIN | N516: 0027 | O516: UT SAN MARTIN | P516: 5-23.BIENES Y SERVICIOS | Q516: 23 2 9 1 1. LOCACIÓN DE SERVICIOS REALIZADOS POR PERSONA NATURAL | R516: 23 2 9 1 1 | S516: LOCACIÓN DE SERVICIOS REALIZADOS POR PERSONA NATURAL | T516: 22500 | U516: 5000 | X516: 5000 | Y516: =+IFERROR(X516/U516,0) -> 1 | Z516: =+U516-X516 -> 0 | AB516: 5000 | AC516: 0 | AD516: 5000 | AF516: 5000 | AG516: =+IFERROR(AF516/U516,0) -> 1 | AH516: =+Tabla1[[#This Row],[PIM]]-Tabla1[[#This Row],[DEVENGADO2]] -> 0 | AI516: 0 | AJ516: 0 | AK516: 2500 | AL516: 2500 | AM516: 0 | AN516: 0 | AO516: 0 | AP516: 0 | AQ516: 0 | AR516: 0 | AS516: 0 | AT516: 0 | AU516: 0 | AV516: =+SUM(AI516:AU516) -> 5000 | AW516: =+U516-AV516 -> 0
A517: 0073.PROGRAMA PARA LA GENERACION DEL EMPLEO SOCIAL INCLUSIVO - TRABAJA PERU | C517: 01. PIA 2026 | D517: 3000001.ACCIONES COMUNES | E517: 5000276.GESTION DEL PROGRAMA | F517: 0047173.GESTION DEL PROGRAMA | G517: AOI00106600164. GESTIÓN OPERATIVA - UT TACNA | H517: CAS | I517: RESTRINGIDA | J517: UFAF | K517: UFAF | L517: UT TACNA | M517: 0028. UT TACNA | N517: 0028 | O517: UT TACNA | P517: 5-21.PERSONAL Y OBLIGACIONES SOCIALES | Q517: 21 1 9 1 4. AGUINALDOS DE CONTRATO ADMINISTRATIVO DE SERVICIOS | R517: 21 1 9 1 4 | S517: AGUINALDOS DE CONTRATO ADMINISTRATIVO DE SERVICIOS | T517: 1200 | U517: 1200 | X517: 1200 | Y517: =+IFERROR(X517/U517,0) -> 1 | Z517: =+U517-X517 -> 0 | AB517: 1200 | AC517: 0 | AD517: 0 | AF517: 0 | AG517: =+IFERROR(AF517/U517,0) -> 0 | AH517: =+Tabla1[[#This Row],[PIM]]-Tabla1[[#This Row],[DEVENGADO2]] -> 1200 | AI517: 0 | AJ517: 0 | AK517: 0 | AL517: 0 | AM517: 0 | AN517: 0 | AO517: 0 | AP517: 600 | AQ517: 0 | AR517: 0 | AS517: 0 | AT517: 0 | AU517: 600 | AV517: =+SUM(AI517:AU517) -> 1200 | AW517: =+U517-AV517 -> 0
A518: 0073.PROGRAMA PARA LA GENERACION DEL EMPLEO SOCIAL INCLUSIVO - TRABAJA PERU | C518: 01. PIA 2026 | D518: 3000001.ACCIONES COMUNES | E518: 5000276.GESTION DEL PROGRAMA | F518: 0047173.GESTION DEL PROGRAMA | G518: AOI00106600164. GESTIÓN OPERATIVA - UT TACNA | H518: CAS | I518: RESTRINGIDA | J518: UFAF | K518: UFAF | L518: UT TACNA | M518: 0028. UT TACNA | N518: 0028 | O518: UT TACNA | P518: 5-21.PERSONAL Y OBLIGACIONES SOCIALES | Q518: 21 113 1 2. CONTRATO ADMINISTRATIVO DE SERVICIOS - TRANSITORIO | R518: 21 113 1 2 | S518: CONTRATO ADMINISTRATIVO DE SERVICIOS - TRANSITORIO | T518: 66340 | U518: 67152 | X518: 67152 | Y518: =+IFERROR(X518/U518,0) -> 1 | Z518: =+U518-X518 -> 0 | AB518: 67152 | AC518: 0 | AD518: 36396.49 | AF518: 36396.49 | AG518: =+IFERROR(AF518/U518,0) -> 0.54200158 | AH518: =+Tabla1[[#This Row],[PIM]]-Tabla1[[#This Row],[DEVENGADO2]] -> 30755.51 | AI518: 5197.57 | AJ518: 5200 | AK518: 5198.92 | AL518: 5200 | AM518: 5200 | AN518: 5200 | AO518: 5200 | AP518: 0 | AQ518: 5528.38 | AR518: 5528.38 | AS518: 5528.38 | AT518: 5528.38 | AU518: 8641.99 | AV518: =+SUM(AI518:AU518) -> 67152 | AW518: =+U518-AV518 -> 0
A519: 0073.PROGRAMA PARA LA GENERACION DEL EMPLEO SOCIAL INCLUSIVO - TRABAJA PERU | C519: 01. PIA 2026 | D519: 3000001.ACCIONES COMUNES | E519: 5000276.GESTION DEL PROGRAMA | F519: 0047173.GESTION DEL PROGRAMA | G519: AOI00106600164. GESTIÓN OPERATIVA - UT TACNA | H519: CAS | I519: RESTRINGIDA | J519: UFAF | K519: UFAF | L519: UT TACNA | M519: 0028. UT TACNA | N519: 0028 | O519: UT TACNA | P519: 5-21.PERSONAL Y OBLIGACIONES SOCIALES | Q519: 21 3 1 115. CONTRIBUCIONES A ESSALUD DE CONTRATO ADMINISTRATIVO DE SERVICIOS | R519: 21 3 1 115 | S519: CONTRIBUCIONES A ESSALUD DE CONTRATO ADMINISTRATIVO DE SERVICIOS | T519: 5520 | U519: 5346 | X519: 5346 | Y519: =+IFERROR(X519/U519,0) -> 1 | Z519: =+U519-X519 -> 0 | AB519: 5346 | AC519: 0 | AD519: 3118.5 | AF519: 3118.5 | AG519: =+IFERROR(AF519/U519,0) -> 0.58333333 | AH519: =+Tabla1[[#This Row],[PIM]]-Tabla1[[#This Row],[DEVENGADO2]] -> 2227.5 | AI519: 445.5 | AJ519: 445.5 | AK519: 445.5 | AL519: 445.5 | AM519: 445.5 | AN519: 445.5 | AO519: 445.5 | AP519: 0 | AQ519: 460 | AR519: 460 | AS519: 460 | AT519: 460 | AU519: 387.5 | AV519: =+SUM(AI519:AU519) -> 5346 | AW519: =+U519-AV519 -> 0
...

Sheet CCP
N2: SEGUIMIENTO A LA EJECUCIÓN DE CCP - 2026
FZ3: PIM | GA3: =+#REF! -> #REF! | GD3: PIM | GE3: =+#REF! -> #REF!
N5: CERTIFICADO (S/) | X5: N° de CCPs | FZ5: Poco avance | GA5: 95 | GB5: 0.98 | GD5: Muy bueno | GE5: 70 | GF5: 0.98
FZ6: TOTAL | GA6: =+SUM(GA5:GA5) -> 95 | GB6: 0 | GD6: TOTAL | GE6: =+SUM(GE5:GE5) -> 70 | GF6: 0
N7: =+DETALLE_CCP!AB4 -> 2.3383864e+08 | X7: =+DETALLE_CCP!R4 -> 1875
FZ8: CERT | GA8: =+#REF! -> #REF! | GD8: dev | GE8: =+#REF! -> #REF!
FZ9: % AVANCE | GA9: =+IFERROR(GA8/GA3,0) -> 0 | GD9: % AVANCE | GE9: =+IFERROR(GE8/GE3,0) -> 0
FZ11: Grados | GA11: =+GA9*PI() -> 0 | GD11: Grados | GE11: =+GE9*PI() -> 0
N12: COMP. ANUAL (S/) | X12: CERT SIN COMP. ANUAL | FZ12: Inicial | GA12: 0 | GB12: 0 | GD12: Inicial | GE12: 0 | GF12: 0
AG13: EJEC. de CCP MENSUAL | FZ13: Final | GA13: =COS(GA11)*-1 -> -1 | GB13: =+SIN(GA11) -> 0 | GD13: Final | GE13: =COS(GE11)*-1 -> -1 | GF13: =+SIN(GE11) -> 0
N14: =+DETALLE_CCP!AC4 -> 1.0179106e+08 | X14: =+N7-N14 -> 1.3204758e+08
AG15: ENE | AI15: =+DETALLE_CCP!AJ4 -> 1066379.2
AG16: FEB | AI16: =+DETALLE_CCP!AK4 -> 1962584.9
AG17: MAR | AI17: =+DETALLE_CCP!AL4 -> 2792982.9
AG18: ABR | AI18: =+DETALLE_CCP!AM4 -> 1.9653967e+08
N19: DEVENGADO (S/) | X19: COMP ANUAL x DEVENGAR (S/) | AG19: MAY | AI19: =+DETALLE_CCP!AN4 -> 2187059.9
AG20: JUN | AI20: =+DETALLE_CCP!AO4 -> 2547006
N21: =+DETALLE_CCP!AF4 -> 2.0959367e+08 | X21: =+N7-N21 -> 24244971 | AG21: JUL | AI21: =+DETALLE_CCP!AP4 -> 2497981.6
AG22: AGO | AI22: =+DETALLE_CCP!AQ4 -> 0
AG23: SET | AI23: =+DETALLE_CCP!AR4 -> 0
AG24: OCT | AI24: =+DETALLE_CCP!AS4 -> 0
AG25: NOV | AI25: =+DETALLE_CCP!AT4 -> 0
AG26: DIC | AI26: =+DETALLE_CCP!AT4 -> 0
N28: ® UNIDAD FUNCIONAL DE PLANEAMIENTO Y PRESUPUESTO
GA35: =+#REF!+1 -> #REF! | GC35: =+#REF!+1 -> #REF! | GE35: =+GC35/$GC$23 -> #REF! | GG35: LABORABLE | GI35: SÁBADO
GA36: =+GA35+1 -> #REF! | GC36: =+GC35+1 -> #REF! | GE36: =+GC36/$GC$23 -> #REF! | GG36: LABORABLE | GI36: DOMINGO
GA37: =+GA36+1 -> #REF! | GC37: =+GC36+1 -> #REF! | GE37: =+GC37/$GC$23 -> #REF! | GG37: LABORABLE | GI37: LUNES
GA38: =+GA37+1 -> #REF! | GC38: =+GC37+1 -> #REF! | GE38: =+GC38/$GC$23 -> #REF! | GG38: LABORABLE | GI38: MARTES
GA39: =+GA38+1 -> #REF! | GC39: =+GC38+1 -> #REF! | GE39: =+GC39/$GC$23 -> #REF! | GG39: LABORABLE | GI39: MIÉRCOLES
GA40: =+#REF!+1 -> #REF! | GC40: =+#REF!+1 -> #REF! | GE40: =+GC40/$GC$23 -> #REF! | GG40: LABORABLE | GI40: VIERNES
GA41: =+GA40+1 -> #REF! | GC41: =+GC40+1 -> #REF! | GE41: =+GC41/$GC$23 -> #REF! | GG41: LABORABLE | GI41: SÁBADO
GA42: =+GA41+1 -> #REF! | GC42: =+GC41+1 -> #REF! | GE42: =+GC42/$GC$23 -> #REF! | GG42: LABORABLE | GI42: DOMINGO
GA43: =+GA42+1 -> #REF! | GC43: =+GC42+1 -> #REF! | GE43: =+GC43/$GC$23 -> #REF! | GG43: LABORABLE | GI43: LUNES
GA44: =+GA43+1 -> #REF! | GC44: =+GC43+1 -> #REF! | GE44: =+GC44/$GC$23 -> #REF! | GG44: LABORABLE | GI44: MARTES
GA45: =+GA44+1 -> #REF! | GC45: =+GC44+1 -> #REF! | GE45: =+GC45/$GC$23 -> #REF! | GG45: LABORABLE | GI45: MIÉRCOLES
GA46: =+GA45+1 -> #REF! | GC46: =+GC45+1 -> #REF! | GE46: =+GC46/$GC$23 -> #REF! | GG46: LABORABLE | GI46: JUEVES
GA47: =+GA46+1 -> #REF! | GC47: =+GC46+1 -> #REF! | GE47: =+GC47/$GC$23 -> #REF! | GG47: LABORABLE | GI47: VIERNES
GA48: =+GA47+1 -> #REF! | GC48: =+GC47+1 -> #REF! | GE48: =+GC48/$GC$23 -> #REF! | GG48: LABORABLE | GI48: SÁBADO
GA49: =+GA48+1 -> #REF! | GC49: =+GC48+1 -> #REF! | GE49: =+GC49/$GC$23 -> #REF! | GG49: LABORABLE | GI49: DOMINGO
GA50: =+GA49+1 -> #REF! | GC50: =+GC49+1 -> #REF! | GE50: =+GC50/$GC$23 -> #REF! | GG50: LABORABLE | GI50: LUNES
...

Sheet DETALLE_CCP
A1: SEGUIMIENTO DE LOS CCP - 2026 | AJ1: DEVENGADO
A2: Fuente: SIAF-MPP, reporte al 31.07.2026 - 09.00am
A4: TOTAL | R4: =+SUBTOTAL(3,Tabla2[CCP]) -> 1875 | AB4: =+SUBTOTAL(9,Tabla2[CERT]) -> 2.3383864e+08 | AC4: =+SUBTOTAL(9,Tabla2[COMP ANUAL]) -> 1.0179106e+08 | AD4: =+AB4-AC4 -> 1.3204758e+08 | AE4: =+SUBTOTAL(9,Tabla2[COMPROMISO]) -> 2.1411364e+08 | AF4: =+SUBTOTAL(9,Tabla2[DEVENGADO]) -> 2.0959367e+08 | AG4: =+AB4-AF4 -> 24244971 | AH4: =+SUBTOTAL(9,Tabla2[GIRADO]) -> 2.0946935e+08 | AI4: =+SUBTOTAL(9,AI7:AI3405) -> 0 | AJ4: =+SUBTOTAL(9,Tabla2[ENE]) -> 1066379.2 | AK4: =+SUBTOTAL(9,Tabla2[FEB]) -> 1962584.9 | AL4: =+SUBTOTAL(9,Tabla2[MAR]) -> 2792982.9 | AM4: =+SUBTOTAL(9,Tabla2[ABR]) -> 1.9653967e+08 | AN4: =+SUBTOTAL(9,Tabla2[MAY]) -> 2187059.9 | AO4: =+SUBTOTAL(9,Tabla2[JUN]) -> 2547006 | AP4: =+SUBTOTAL(9,Tabla2[JUL]) -> 2497981.6 | AQ4: =+SUBTOTAL(9,Tabla2[AGO]) -> 0 | AR4: =+SUBTOTAL(9,Tabla2[SEP]) -> 0 | AS4: =+SUBTOTAL(9,Tabla2[OCT]) -> 0 | AT4: =+SUBTOTAL(9,Tabla2[NOV]) -> 0 | AU4: =+SUBTOTAL(9,Tabla2[DIC]) -> 0
A6: fecha_doc | B6: MES DE APROBADO CCP | C6: Estado | D6: CENTRO DE COSTO | E6: DISPOSITIVO LEGAL | F6: PROG. PPTAL. | G6: ACT. PPTAL. | H6: CONCEPTO DE GASTO | I6: RESTRINGIDA / NO RESTRINGIDA | J6: OF. NAC. / UT / TRANSF | K6: UNIDAD / UT | L6: EXP. SIAF | M6: N° O/S | N6: FECHA O/S | O6: RUC PROVEEDOR | P6: NOMBRE PROVEEDOR | Q6: Fte. Fto. | R6: CCP | S6: Glosa Certificación | T6: N° de CCP + Glosa | U6: Sec. Fun. | V6: Nemonico Sec.Fun. | W6: Sec. fun. + Nemonico | X6: Gen de Gastos | Y6: Clasificador | Z6: DESCRIPCIÓN | AA6: Clasif + Desc. | AB6: CERT | AC6: COMP ANUAL | AD6: SALDO (CERT - COMP ANUAL) | AE6: COMPROMISO | AF6: DEVENGADO | AG6: SALDO (COMP. ANUAL - DEV) | AH6: GIRADO | AI6: . | AJ6: ENE | AK6: FEB | AL6: MAR | AM6: ABR | AN6: MAY | AO6: JUN | AP6: JUL | AQ6: AGO | AR6: SEP | AS6: OCT | AT6: NOV | AU6: DIC | AV6: CERT POR COMP ANUAL | AW6: COMP. ANUAL POR DEVENGAR | AX6: SERVICIO
A7: 46035 | B7: 01. ENE | C7: APROBADO | D7: UFAF | E7: 01. PIA 2026 | F7: 3000001.ACCIONES COMUNES | G7: 5000276.GESTION DEL PROGRAMA | H7: DIFUSION EN EL PERUANO | I7: NO RESTRINGIDA | J7: OFICINA NACIONAL | K7: UFAF | L7: 0000000003 | M7: 12229 | N7: 08/01/2026 | O7: 0 | P7: 0000000001 | 12229 | SIN NOMBRE | Q7: 00 | R7: 0000000001 | S7: CCMN-000036: CONTRATACION DEL SERVICIO DE PUBLICACION EN EL DIARIO OFICIAL EL PERUANO | T7: 0000000001. CCMN-000036: CONTRATACION DEL SERVICIO DE PUBLICACION EN EL DIARIO OFICIAL EL PERUANO | U7: 0014 | V7: UFAF | W7: 0014. UFAF | X7: 5-23. BIENES Y SERVICIOS | Y7: 23 2 2 5 1 | Z7: DIFUSIÓN EN EL DIARIO OFICIAL | AA7: 23 2 2 5 1. DIFUSIÓN EN EL DIARIO OFICIAL | AB7: 20000 | AC7: 20000 | AD7: 0 | AE7: 20000 | AF7: 1286.86 | AG7: 18713.14 | AH7: 1286.86 | AI7: 2026 | AJ7: 1286.86 | AK7: 0 | AL7: 0 | AM7: 0 | AN7: 0 | AO7: 0 | AP7: 0 | AQ7: 0 | AR7: 0 | AS7: 0 | AT7: 0 | AU7: 0 | AV7: CCP SIN SALDO | AW7: CCP POR DEVENGAR | AX7: -
A8: 46035 | B8: 01. ENE | C8: APROBADO | D8: UFAF | E8: 01. PIA 2026 | F8: 3000001.ACCIONES COMUNES | G8: 5000276.GESTION DEL PROGRAMA | H8: AGUA DE MESA | I8: NO RESTRINGIDA | J8: OFICINA NACIONAL | K8: UFAF | L8: 0000000007 | M8: 0000001 | N8: 15/01/2026 | O8: 20340549750 | P8: 0000000002 | 0000001 | CONQUISTADORES REAL SERVICE S.A. | Q8: 00 | R8: 0000000002 | S8: CCMN-000001: ADQUISICION DE AGUA DE MESA PARA LA OFICINA NACIONAL, ARCHIVO CENTRAL Y UNIDADES TERRITORIALES LIMA | T8: 0000000002. CCMN-000001: ADQUISICION DE AGUA DE MESA PARA LA OFICINA NACIONAL, ARCHIVO CENTRAL Y UNIDADES TERRITORIALES LIMA | U8: 0014 | V8: UFAF | W8: 0014. UFAF | X8: 5-23. BIENES Y SERVICIOS | Y8: 23 1 1 1 1 | Z8: ALIMENTOS Y BEBIDAS PARA CONSUMO HUMANO | AA8: 23 1 1 1 1. ALIMENTOS Y BEBIDAS PARA CONSUMO HUMANO | AB8: 16800 | AC8: 16800 | AD8: 0 | AE8: 16800 | AF8: 14400 | AG8: 2400 | AH8: 14400 | AI8: 2026 | AJ8: 2400 | AK8: 2400 | AL8: 2400 | AM8: 2400 | AN8: 2400 | AO8: 0 | AP8: 2400 | AQ8: 0 | AR8: 0 | AS8: 0 | AT8: 0 | AU8: 0 | AV8: CCP SIN SALDO | AW8: CCP POR DEVENGAR | AX8: -
A9: 46035 | B9: 01. ENE | C9: APROBADO | D9: UFAF | E9: 01. PIA 2026 | F9: 3000001.ACCIONES COMUNES | G9: 5000276.GESTION DEL PROGRAMA | H9: LOCADORES | I9: NO RESTRINGIDA | J9: OFICINA NACIONAL | K9: UFAF | L9: 0000000011 | M9: 0000008 | N9: 15/01/2026 | O9: 10444528121 | P9: 0000000003 | 0000008 | GALLOSO ROSAS YULIANA LIZBETH | Q9: 00 | R9: 0000000003 | S9: CCMN-002013: CONTRATACION DEL SERVICIO DE SEGUIMIENTO Y MONITOREO DE SERVICIOS GENERALES DE LA COORDINACION FUNCI | T9: 0000000003. CCMN-002013: CONTRATACION DEL SERVICIO DE SEGUIMIENTO Y MONITOREO DE SERVICIOS GENERALES DE LA COORDINACION FUNCI | U9: 0014 | V9: UFAF | W9: 0014. UFAF | X9: 5-23. BIENES Y SERVICIOS | Y9: 23 2 9 1 1 | Z9: LOCACIÓN DE SERVICIOS REALIZADOS POR PERSONA NATURAL | AA9: 23 2 9 1 1. LOCACIÓN DE SERVICIOS REALIZADOS POR PERSONA NATURAL | AB9: 6000 | AC9: 6000 | AD9: 0 | AE9: 6000 | AF9: 6000 | AG9: 0 | AH9: 6000 | AI9: 2026 | AJ9: 6000 | AK9: 0 | AL9: 0 | AM9: 0 | AN9: 0 | AO9: 0 | AP9: 0 | AQ9: 0 | AR9: 0 | AS9: 0 | AT9: 0 | AU9: 0 | AV9: CCP SIN SALDO | AW9: CCP DEVENGADO | AX9: LOCADOR
A10: 46035 | B10: 01. ENE | C10: APROBADO | D10: UFAF | E10: 01. PIA 2026 | F10: 3000001.ACCIONES COMUNES | G10: 5000276.GESTION DEL PROGRAMA | H10: LOCADORES | I10: NO RESTRINGIDA | J10: OFICINA NACIONAL | K10: UFAF | L10: 0000000042 | M10: 0000034 | N10: 16/01/2026 | O10: 10740657238 | P10: 0000000004 | 0000034 | SANCA BUSTAMANTE JHONATHAN ALEXANDER | Q10: 00 | R10: 0000000004 | S10: CCMN-002007: SERVICIOS DE ANALISIS DE PROCESOS DE CONTRATACIONES MENORES O IGUALES A 8 UIT | T10: 0000000004. CCMN-002007: SERVICIOS DE ANALISIS DE PROCESOS DE CONTRATACIONES MENORES O IGUALES A 8 UIT | U10: 0014 | V10: UFAF | W10: 0014. UFAF | X10: 5-23. BIENES Y SERVICIOS | Y10: 23 2 9 1 1 | Z10: LOCACIÓN DE SERVICIOS REALIZADOS POR PERSONA NATURAL | AA10: 23 2 9 1 1. LOCACIÓN DE SERVICIOS REALIZADOS POR PERSONA NATURAL | AB10: 7000 | AC10: 7000 | AD10: 0 | AE10: 7000 | AF10: 7000 | AG10: 0 | AH10: 7000 | AI10: 2026 | AJ10: 7000 | AK10: 0 | AL10: 0 | AM10: 0 | AN10: 0 | AO10: 0 | AP10: 0 | AQ10: 0 | AR10: 0 | AS10: 0 | AT10: 0 | AU10: 0 | AV10: CCP SIN SALDO | AW10: CCP DEVENGADO | AX10: LOCADOR
A11: 46035 | B11: 01. ENE | C11: APROBADO | D11: UFSMI | E11: 01. PIA 2026 | F11: 3000194.EMPLEO TEMPORAL GENERADO | G11: 5006296.SEGUIMIENTO DE LOS PROYECTOS Y ACTIVIDADES EN EJECUCION | H11: LOCADORES | I11: NO RESTRINGIDA | J11: OFICINA NACIONAL | K11: UFSMI | L11: 0000000045 | M11: 0000037 | N11: 16/01/2026 | O11: 10182169922 | P11: 0000000005 | 0000037 | MELGAR OCAMPOS FREDY RONALD | Q11: 00 | R11: 0000000005 | S11: CCMN-002008: SERVICIO DE SUPERVISION, SEGUIMIENTO Y MONITOREO A LA EJECUCION DE PROYECTOS DE INVERSION Y ACTIVIDA | T11: 0000000005. CCMN-002008: SERVICIO DE SUPERVISION, SEGUIMIENTO Y MONITOREO A LA EJECUCION DE PROYECTOS DE INVERSION Y ACTIVIDA | U11: 0056 | V11: UFSMI | W11: 0056. UFSMI | X11: 5-23. BIENES Y SERVICIOS | Y11: 23 2 9 1 1 | Z11: LOCACIÓN DE SERVICIOS REALIZADOS POR PERSONA NATURAL | AA11: 23 2 9 1 1. LOCACIÓN DE SERVICIOS REALIZADOS POR PERSONA NATURAL | AB11: 8000 | AC11: 8000 | AD11: 0 | AE11: 8000 | AF11: 8000 | AG11: 0 | AH11: 8000 | AI11: 2026 | AJ11: 8000 | AK11: 0 | AL11: 0 | AM11: 0 | AN11: 0 | AO11: 0 | AP11: 0 | AQ11: 0 | AR11: 0 | AS11: 0 | AT11: 0 | AU11: 0 | AV11: CCP SIN SALDO | AW11: CCP DEVENGADO | AX11: LOCADOR
A12: 46035 | B12: 01. ENE | C12: APROBADO | D12: UFAJ | E12: 01. PIA 2026 | F12: 3000001.ACCIONES COMUNES | G12: 5000276.GESTION DEL PROGRAMA | H12: LOCADORES | I12: NO RESTRINGIDA | J12: OFICINA NACIONAL | K12: UFAJ | L12: 0000000044 | M12: 0000036 | N12: 16/01/2026 | O12: 10481279700 | P12: 0000000006 | 0000036 | MORA ASNARAN FERNANDO | Q12: 00 | R12: 0000000006 | S12: CCMN-002009: SERVICIOS DE ANALISIS Y ELABORACION DE INFORMES EN TEMAS LEGALES | T12: 0000000006. CCMN-002009: SERVICIOS DE ANALISIS Y ELABORACION DE INFORMES EN TEMAS LEGALES | U12: 0015 | V12: UFAJ | W12: 0015. UFAJ | X12: 5-23. BIENES Y SERVICIOS | Y12: 23 2 9 1 1 | Z12: LOCACIÓN DE SERVICIOS REALIZADOS POR PERSONA NATURAL | AA12: 23 2 9 1 1. LOCACIÓN DE SERVICIOS REALIZADOS POR PERSONA NATURAL | AB12: 8000 | AC12: 8000 | AD12: 0 | AE12: 8000 | AF12: 8000 | AG12: 0 | AH12: 8000 | AI12: 2026 | AJ12: 8000 | AK12: 0 | AL12: 0 | AM12: 0 | AN12: 0 | AO12: 0 | AP12: 0 | AQ12: 0 | AR12: 0 | AS12: 0 | AT12: 0 | AU12: 0 | AV12: CCP SIN SALDO | AW12: CCP DEVENGADO | AX12: LOCADOR
A13: 46035 | B13: 01. ENE | C13: APROBADO | D13: UFAF | E13: 01. PIA 2026 | F13: 3000001.ACCIONES COMUNES | G13: 5000276.GESTION DEL PROGRAMA | H13: LOCADORES | I13: NO RESTRINGIDA | J13: OFICINA NACIONAL | K13: UFAF | L13: 0000000048 | M13: 0000040 | N13: 16/01/2026 | O13: 10719216124 | P13: 0000000007 | 0000040 | SANTANA DAZA PIERO ANGEL | Q13: 00 | R13: 0000000007 | S13: CCMN-002011: SERVICIO ANALISIS Y SEGUIMIENTO ADMINISTRATIVO Y PRESUPUESTAL - UFAF | T13: 0000000007. CCMN-002011: SERVICIO ANALISIS Y SEGUIMIENTO ADMINISTRATIVO Y PRESUPUESTAL - UFAF | U13: 0014 | V13: UFAF | W13: 0014. UFAF | X13: 5-23. BIENES Y SERVICIOS | Y13: 23 2 9 1 1 | Z13: LOCACIÓN DE SERVICIOS REALIZADOS POR PERSONA NATURAL | AA13: 23 2 9 1 1. LOCACIÓN DE SERVICIOS REALIZADOS POR PERSONA NATURAL | AB13: 7500 | AC13: 7500 | AD13: 0 | AE13: 7500 | AF13: 7500 | AG13: 0 | AH13: 7500 | AI13: 2026 | AJ13: 7500 | AK13: 0 | AL13: 0 | AM13: 0 | AN13: 0 | AO13: 0 | AP13: 0 | AQ13: 0 | AR13: 0 | AS13: 0 | AT13: 0 | AU13: 0 | AV13: CCP SIN SALDO | AW13: CCP DEVENGADO | AX13: LOCADOR
